Workbook

Sheet Read me
A1: Item | B1: Detail
A2: Purpose | B2: User acceptance test script for the Tanmark Industries order-to-cash, procure-to-pay and accounting system. Tanmark Industries is fictional; every name and number is illustrative.
A3: Version | B3: v5, 2026-09-30 (map steps per row, test data, defects)
A4: Owner | B4: Product owner (role). Each department signs the stories it owns on the Sign-off sheet.
A5: How to use | B5: Run each row as written. Record what happened in Actual. Choose Pass, Fail or Blocked in Result. A Fail needs a defect id in Actual.
A6: Where rows come from | B6: Generated from stories/*.feature by uat/build_uat.py and checked against the state model (state/transitions.csv) and the after map (process/after.bpmn).
A7: State transition | B7: The move the row exercises (from state: event, to state), the state it checks, or the move it proves refused.
A8: Not tested as a row | B8: Refused moves in the model that no row tests: delivery-trip, Delivered: edit times or quantities; delivery-trip, Planned: edit when the order is closed; sales-order, Completed: edit; sales-order, Receiving and shipping: cancel. A choice, not a gap: each is enforced by the same rule as a tested move.
A9: Shaded cells | B9: Cells shaded pale yellow are for the tester. Everything else is generated, including the suggested tester role, which the tester may change.
A10: Map steps | B10: Each row names the step on process/after.bpmn that makes its move, or, for a state or a refusal, the steps that move the document on from that state.
A11: Test data | B11: Every record the rows use, the states they start it in, and the rows that use it: load these before testing.
A12: Defects | B12: One row per defect, tied to a UAT row. Severity 1 blocks a process or breaks a rule; 2 works with a workaround; 3 is cosmetic. An open severity 1 defect stops the go-live (cutover plan, criterion 2), and the Sign-off sheet counts them per story.

Sheet UAT
A1: ID | B1: Story | C1: Scenario | D1: Document | E1: State transition | F1: Rule | G1: Map steps | H1: Decisions | I1: Steps | J1: Expected | K1: Actual | L1: Result | M1: Tester role | N1: Date
A2: UAT-01 | B2: delivery-trip | C2: The warehouse issues exactly the planned quantity | D2: delivery-trip | E2: Planned: issue, to Issued | F2: R5 | G2: T16 | H2: D14, D15, D16 | I2: Given order "SO-2050" is "Receiving and shipping" And trip "TR-118" is planned to deliver 5 of "Container C-20" for it When the warehouse keeper issues 5 of "Container C-20" to trip "TR-118" | J2: Then trip "TR-118" shows the state "Issued" And stock of "Container C-20" falls by 5 And the issue form downloads with its form number | M2: Warehouse keeper
A3: UAT-02 | B3: delivery-trip | C3: The trip leaves once it is issued | D3: delivery-trip | E3: Issued: dispatch, to In transit | F3: R9 | G3: T17 | H3: D14, D15, D16 | I3: Given order "SO-2050" is "Receiving and shipping" And trip "TR-118" is planned to deliver 5 of "Container C-20" for it Given trip "TR-118" is "Issued" And its invoice "INV-390" is "Raised" When the logistics coordinator dispatches the trip with a departure time | J3: Then trip "TR-118" shows the state "In transit" | M3: Logistics coordinator
A4: UAT-03 | B4: delivery-trip | C4: A delivered trip is read-only | D4: delivery-trip | E4: In transit: confirm delivery, to Delivered | F4: R4 | G4: T10, T16, T11, T17 | H4: D14, D15, D16 | I4: Given order "SO-2050" is "Receiving and shipping" And trip "TR-118" is planned to deliver 5 of "Container C-20" for it Given trip "TR-118" is "In transit" When the logistics coordinator confirms delivery with an arrival time | J4: Then trip "TR-118" shows the state "Delivered" And its times and quantities can no longer be changed | M4: Logistics coordinator
A5: UAT-04 | B5: delivery-trip | C5: The warehouse cannot issue a different quantity | D5: delivery-trip | E5: refused in Planned: issue a different quantity | F5: R5 | G5: T16 | H5: D14, D15, D16 | I5: Given order "SO-2050" is "Receiving and shipping" And trip "TR-118" is planned to deliver 5 of "Container C-20" for it When the warehouse keeper tries to issue 4 of "Container C-20" to trip "TR-118" | J5: Then the issue is refused And the warehouse keeper sees "Issue exactly the plan, or revise the plan first." | M5: Warehouse keeper
A6: UAT-05 | B6: delivery-trip | C6: A numbered issue form cannot exist before the goods are issued | D6: delivery-trip | E6: refused in Planned: download numbered form | F6: R8 | G6: T16 | H6: D14, D15, D16 | I6: Given order "SO-2050" is "Receiving and shipping" And trip "TR-118" is planned to deliver 5 of "Container C-20" for it Given trip "TR-118" is "Planned" When the warehouse keeper tries to download the numbered issue form | J6: Then the download is refused And the warehouse keeper sees "No stock has moved yet. Preview the draft form; its number is given when the goods are issued." | M6: Warehouse keeper
A7: UAT-06 | B7: delivery-trip | C7: A trip cannot leave without its invoice | D7: delivery-trip | E7: refused in Issued: dispatch without an invoice | F7: R9 | G7: T17 | H7: D14, D15, D16 | I7: Given order "SO-2050" is "Receiving and shipping" And trip "TR-118" is planned to deliver 5 of "Container C-20" for it Given trip "TR-118" is "Issued" And no invoice has been raised for it When the logistics coordinator tries to dispatch the trip | J7: Then the dispatch is refused And the coordinator sees "Goods leave only with their invoice. Raise the trip's invoice first." | M7: Logistics coordinator
A8: UAT-07 | B8: material-request | C8: A numbered issue form cannot exist before the materials are issued | D8: material-request | E8: refused in Open: download numbered form | F8: R8 | G8: T7 | H8: D6, D15 | I8: Given order "SO-2070" for 300 steel drums is "In production" And material request "MR-310" for it asks for 400 kg of "Steel sheet 1.2 mm" And the factory manager is assigned to "MR-310" Given material request "MR-310" is "Open" When the warehouse keeper tries to download the numbered issue form | J8: Then the download is refused And the warehouse keeper sees "No stock has moved yet. Preview the draft form; its number is given when the materials are issued." | M8: Warehouse keeper
A9: UAT-08 | B9: material-request | C9: The first issue starts the request | D9: material-request | E9: Open: issue first materials, to Issuing | F9: R8 | G9: T7 | H9: D6, D15 | I9: Given order "SO-2070" for 300 steel drums is "In production" And material request "MR-310" for it asks for 400 kg of "Steel sheet 1.2 mm" And the factory manager is assigned to "MR-310" Given material request "MR-310" is "Open" When the warehouse keeper issues 250 kg to the drum workshop | J9: Then "MR-310" shows the state "Issuing" And stock of "Steel sheet 1.2 mm" falls by 250 kg And the issue form downloads with its form number | M9: Warehouse keeper
A10: UAT-09 | B10: material-request | C10: A second issue gets its own form | D10: material-request | E10: Issuing: issue more materials, to Issuing | F10: R8 | G10: T4, T7 | H10: D6, D15 | I10: Given order "SO-2070" for 300 steel drums is "In production" And material request "MR-310" for it asks for 400 kg of "Steel sheet 1.2 mm" And the factory manager is assigned to "MR-310" Given material request "MR-310" is "Issuing" with 150 kg still open When the warehouse keeper issues 100 kg to the drum workshop | J10: Then "MR-310" still shows the state "Issuing" And a new issue form downloads with its own form number | M10: Warehouse keeper
A11: UAT-10 | B11: material-request | C11: The last issue completes the request | D11: material-request | E11: Issuing: issue last materials, to Completed | F11: R8 | G11: T4, T7 | H11: D6, D15 | I11: Given order "SO-2070" for 300 steel drums is "In production" And material request "MR-310" for it asks for 400 kg of "Steel sheet 1.2 mm" And the factory manager is assigned to "MR-310" Given material request "MR-310" is "Issuing" with 50 kg still open When the warehouse keeper issues the last 50 kg | J11: Then "MR-310" shows the state "Completed" | M11: Warehouse keeper
A12: UAT-11 | B12: material-request | C12: A request that has issued materials cannot be cancelled | D12: material-request | E12: refused in Issuing: cancel | F12: R3 | G12: T4, T7 | H12: D6, D15 | I12: Given order "SO-2070" for 300 steel drums is "In production" And material request "MR-310" for it asks for 400 kg of "Steel sheet 1.2 mm" And the factory manager is assigned to "MR-310" Given material request "MR-310" is "Issuing" When the factory manager tries to cancel it | J12: Then the cancellation is refused And the factory manager sees "Materials have left the warehouse. Complete the request, or close the order as Not completed." | M12: Factory manager
A13: UAT-12 | B13: material-request | C13: A request with nothing issued can be cancelled, and is kept | D13: material-request | E13: Open: cancel, to Cancelled | F13: R1 | G13: T4, T7 | H13: D6, D15 | I13: Given order "SO-2070" for 300 steel drums is "In production" And material request "MR-310" for it asks for 400 kg of "Steel sheet 1.2 mm" And the factory manager is assigned to "MR-310" Given material request "MR-311" is "Open" and nothing has been issued against it When the factory manager cancels it | J13: Then "MR-311" shows the state "Cancelled" And it keeps its number | M13: Factory manager
... A15: UAT-14 | B15: order-closure | C15: An order in production closes as not completed | D15: sales-order | E15: In production: close as not completed, to Not completed | F15: R3 | G15: T15 | H15: D6, D10 | I15: Given order "SO-2041" is "In production" And 4 of its 10 tank bodies have been received into stock When the sales manager closes it as not completed | J15: Then it shows the state "Not completed" And the 4 received assemblies stay in stock And the 6 not yet made drop out of open demand | M15: Sales manager
A16: UAT-15 | B16: order-closure | C16: Nothing is removed when an order closes | D16: sales-order | E16: in state: Cancelled | F16: R1 | G16: G0, T14, G3, T15 | H16: D6, D10 | I16: Given order "SO-2040" is "Cancelled" When anyone searches for order "SO-2040" | J16: Then the order is found with its history
A17: UAT-16 | B17: order-closure | C17: An order in production cannot be cancelled | D17: sales-order | E17: refused in In production: cancel | F17: R3 | G17: T15, T9 | H17: D6, D10 | I17: Given order "SO-2041" is "In production" When the sales manager tries to cancel it | J17: Then the cancellation is refused And the sales manager sees "Production has started. Close the order as Not completed instead." And order "SO-2041" still shows the state "In production" | M17: Sales manager
A18: UAT-17 | B18: order-lifecycle | C18: A saved request does not start fulfilment | D18: sales-order | E18: in state: Request | F18: none | G18: T2, T18 | H18: D5, D7, D17 | I18: Given customer "C-104" is on file And "Steel drum D-200" is a product Tanmark sells Given Sam saves an order request for 6 of "Steel drum D-200" for customer "C-104" When logistics opens its work list | J18: Then the request is not on it And the request shows the state "Request"
A19: UAT-18 | B19: order-lifecycle | C19: Confirming the request makes it an order | D19: sales-order | E19: Request: confirm order, to Open | F19: none | G19: T2 | H19: D5, D7, D17 | I19: Given customer "C-104" is on file And "Steel drum D-200" is a product Tanmark sells Given Sam's request for 6 of "Steel drum D-200" is complete When Sam confirms the order | J19: Then it shows the state "Open" And it has an order number | M19: Sales staff
A20: UAT-19 | B20: order-lifecycle | C20: A customer on credit hold gets no new order | D20: sales-order | E20: refused in Request: confirm on credit hold | F20: R10 | G20: T2, T18 | H20: D5, D7, D17 | I20: Given customer "C-104" is on file And "Steel drum D-200" is a product Tanmark sells Given contract "K-104-2" of customer "C-104" is on credit hold And Sam's request for 6 of "Steel drum D-200" is complete When Sam tries to confirm the order | J20: Then the confirmation is refused And Sam sees "The customer is over its credit limit or overdue. The chief accountant must release the order." And the request still shows the state "Request" | M20: Sales staff
A21: UAT-20 | B21: order-lifecycle | C21: The chief accountant releases one order, with a reason | D21: sales-order | E21: Request: confirm with credit release, to Open | F21: R10 | G21: T18 | H21: D5, D7, D17 | I21: Given customer "C-104" is on file And "Steel drum D-200" is a product Tanmark sells Given contract "K-104-2" of customer "C-104" is on credit hold And Sam's request for 6 of "Steel drum D-200" is complete When the chief accountant releases the order with the reason "Overdue invoice paid today; transfer confirmed" | J21: Then it shows the state "Open" And the release is logged with the chief accountant's name and the reason | M21: Chief accountant
A22: UAT-21 | B22: order-lifecycle | C22: Sending the order to logistics locks it for sales | D22: sales-order | E22: Open: send to logistics, to With logistics | F22: R6 | G22: T3 | H22: D5, D7, D17 | I22: Given customer "C-104" is on file And "Steel drum D-200" is a product Tanmark sells Given order "SO-2031" is "Open" with a salesperson assigned When Sam sends it to logistics | J22: Then it shows the state "With logistics" And the logistics coordinator sees it on the work list | M22: Sales staff
A23: UAT-22 | B23: order-lifecycle | C23: Sales cannot edit an order that logistics has | D23: sales-order | E23: refused in With logistics: sales edit | F23: R6 | G23: T14, T4 | H23: D5, D7, D17 | I23: Given customer "C-104" is on file And "Steel drum D-200" is a product Tanmark sells Given order "SO-2031" is "With logistics" When Sam tries to change its quantity from 6 to 8 | J23: Then the change is refused And Sam sees "After handoff, sales cannot edit the order. Raise a new order for an increase." And order "SO-2031" still shows a quantity of 6 | M23: Sales staff
A24: UAT-23 | B24: purchase-order | C24: A new purchase order is open at once | D24: purchase-order | E24: in state: Open | F24: none | G24: T6 | H24: D9, D15 | I24: Given the buyer holds a signed paper request for 200 kg of "Stainless bar S-40" When the buyer creates purchase order "PO-5110" with supplier "V-07" | J24: Then it shows the state "Open" And no approval task is created
A25: UAT-24 | B25: purchase-order | C25: The warehouse keeper reviews a draft receipt form before receiving | D25: purchase-order | E25: in state: Open | F25: R8 | G25: T6 | H25: D9, D15 | I25: Given purchase order "PO-5110" is "Open" When the warehouse keeper previews the receipt form | J25: Then the form downloads marked "Draft" with no form number And purchase order "PO-5110" still shows the state "Open"
A26: UAT-25 | B26: purchase-order | C26: A numbered receipt form cannot exist before the goods are received | D26: purchase-order | E26: refused in Open: download numbered form | F26: R8 | G26: T6 | H26: D9, D15 | I26: Given purchase order "PO-5110" is "Open" When the warehouse keeper tries to download the numbered receipt form | J26: Then the download is refused And the warehouse keeper sees "No stock has moved yet. Preview the draft form; its number is given when the goods are received." | M26: Warehouse keeper
A27: UAT-26 | B27: purchase-order | C27: Receiving the goods counts as approval | D27: purchase-order | E27: Open: receive into stock, to Received | F27: R8 | G27: T6 | H27: D9, D15 | I27: Given purchase order "PO-5110" is "Open" When the warehouse keeper receives 200 kg into stock against it | J27: Then it shows the state "Received" And stock of "Stainless bar S-40" rises by 200 kg And the receipt form downloads with its form number | M27: Warehouse keeper
A28: UAT-27 | B28: purchase-order | C28: A second delivery gets its own receipt form | D28: purchase-order | E28: Received: receive more, to Received | F28: R8 | G28: T5, T6 | H28: D9, D15 | I28: Given purchase order "PO-5120" for 300 kg of "Stainless bar S-40" has received 200 kg When the warehouse keeper receives the remaining 100 kg against it | J28: Then it still shows the state "Received" And a new receipt form downloads with its own form number | M28: Warehouse keeper
A29: UAT-28 | B29: purchase-order | C29: The order closes when every line is received and invoiced | D29: purchase-order | E29: Received: close, to Completed | F29: none | G29: T5, T6 | H29: D9, D15 | I29: Given purchase order "PO-5110" is "Received" And the supplier's invoice for it is recorded When the buyer closes it | J29: Then it shows the state "Completed" | M29: Purchasing staff
A30: UAT-29 | B30: purchase-order | C30: A received purchase order cannot be cancelled | D30: purchase-order | E30: refused in Received: cancel | F30: R3 | G30: T5, T6 | H30: D9, D15 | I30: Given purchase order "PO-5110" is "Received" When the buyer tries to cancel it | J30: Then the cancellation is refused And the buyer sees "Goods are in stock. Return them to the supplier instead." | M30: Purchasing staff
A31: UAT-30 | B31: receivables | C31: The invoice is raised for the issued trip, with its due date from the contract | D31: sales-invoice | E31: Draft: raise, to Raised | F31: R9 | G31: T11 | H31: D16, D17 | I31: Given customer "C-104" buys under contract "K-104-2" with 30-day payment terms And trip "TR-131" for order "SO-2060" is "Issued" When the accountant raises the invoice for trip "TR-131" on 2 March for 5,000.00 | J31: Then invoice "INV-401" shows the state "Raised" And its due date is 1 April | M31: Accountant
A32: UAT-31 | B32: receivables | C32: A trip that has not been issued cannot be invoiced | D32: sales-invoice | E32: refused in Draft: raise before the trip is issued | F32: R9 | G32: T11 | H32: D16, D17 | I32: Given customer "C-104" buys under contract "K-104-2" with 30-day payment terms And trip "TR-131" for order "SO-2060" is "Issued" Given trip "TR-132" for order "SO-2060" is "Planned" When the accountant tries to raise the invoice for trip "TR-132" | J32: Then the invoice is refused And the accountant sees "Raise the invoice for goods the warehouse has issued to the trip." | M32: Accountant
A33: UAT-32 | B33: receivables | C33: One transfer pays the oldest invoice first | D33: sales-invoice | E33: Raised: record part payment, to Partly paid | F33: none | G33: T11, T12 | H33: D16, D17 | I33: Given customer "C-104" buys under contract "K-104-2" with 30-day payment terms And trip "TR-131" for order "SO-2060" is "Issued" Given invoice "INV-401" for 5,000.00 due 1 April is "Raised" And invoice "INV-402" for 3,000.00 due 4 April is "Raised" And the trips for both invoices are confirmed delivered When customer "C-104" transfers 6,000.00 and the receipt is allocated | J33: Then invoice "INV-401" shows the state "Paid" And invoice "INV-402" shows the state "Partly paid" with 2,000.00 still due | M33: Accountant
A34: UAT-33 | B34: receivables | C34: The last payment clears the invoice | D34: sales-invoice | E34: Partly paid: record final payment, to Paid | F34: none | G34: T11, T12 | H34: D16, D17 | I34: Given customer "C-104" buys under contract "K-104-2" with 30-day payment terms And trip "TR-131" for order "SO-2060" is "Issued" Given invoice "INV-402" is "Partly paid" with 2,000.00 still due When customer "C-104" transfers 2,000.00 and the receipt is allocated | J34: Then invoice "INV-402" shows the state "Paid" | M34: Accountant
A35: UAT-34 | B35: receivables | C35: An invoice past its due date shows in the ageing view and holds the contract | D35: sales-invoice | E35: in state: Raised | F35: R10 | G35: T11, T12 | H35: D16, D17 | I35: Given customer "C-104" buys under contract "K-104-2" with 30-day payment terms And trip "TR-131" for order "SO-2060" is "Issued" Given invoice "INV-405" for 4,000.00 due 1 April is "Raised" When the ageing view is run on 20 April | J35: Then invoice "INV-405" shows 19 days overdue, in the 1 to 30 days column And contract "K-104-2" shows "On credit hold"
A36: UAT-35 | B36: receivables | C36: A price correction is a part credit note, not an edit | D36: sales-invoice | E36: Raised: credit in part, to Raised | F36: R2 | G36: T11, T12 | H36: D16, D17 | I36: Given customer "C-104" buys under contract "K-104-2" with 30-day payment terms And trip "TR-131" for order "SO-2060" is "Issued" Given invoice "INV-401" for 5,000.00 is "Raised" When the chief accountant issues a credit note for 300.00 against it, with the reason "agreed price correction" | J36: Then invoice "INV-401" still shows the state "Raised" And its balance due is 4,700.00 And the original amount of 5,000.00 is unchanged | M36: Chief accountant
A37: UAT-36 | B37: receivables | C37: An invoice amount cannot be edited | D37: sales-invoice | E37: refused in Raised: edit amount | F37: R2 | G37: T11, T12 | H37: D16, D17 | I37: Given customer "C-104" buys under contract "K-104-2" with 30-day payment terms And trip "TR-131" for order "SO-2060" is "Issued" Given invoice "INV-401" for 5,000.00 is "Raised" When the accountant tries to change its amount to 4,500.00 | J37: Then the change is refused And the accountant sees "Correct an invoice with a credit note, never by editing it." | M37: Accountant
A38: UAT-37 | B38: sale-statuses | C38: A new sale starts with all three statuses open | D38: sale-statuses | E38: in state: Not invoiced, Not delivered, Unpaid | F38: none | G38: T11, T17, T12 | H38: D8, D16, D17 | I38: Given order "SO-2060" for 8,000.00 ships on two trips And trip "TR-131" carries 5,000.00 of it and trip "TR-132" carries 3,000.00 And customer "C-104" buys under contract "K-104-2" with 30-day payment terms When order "SO-2060" is confirmed | J38: Then its statuses are "Not invoiced", "Not delivered" and "Unpaid"
A39: UAT-38 | B39: sale-statuses | C39: The first trip's invoice makes the sale partly invoiced | D39: sale-statuses | E39: Not invoiced: first trip invoiced, to Partly invoiced | F39: none | G39: T11, T17, T12 | H39: D8, D16, D17 | I39: Given order "SO-2060" for 8,000.00 ships on two trips And trip "TR-131" carries 5,000.00 of it and trip "TR-132" carries 3,000.00 And customer "C-104" buys under contract "K-104-2" with 30-day payment terms When the invoice for trip "TR-131" is raised | J39: Then its statuses are "Partly invoiced", "Not delivered" and "Unpaid"
A40: UAT-39 | B40: sale-statuses | C40: Delivery never runs ahead of invoicing | D40: sale-statuses | E40: Not delivered: first trip delivered, to Partly delivered | F40: none | G40: T11, T17, T12 | H40: D8, D16, D17 | I40: Given order "SO-2060" for 8,000.00 ships on two trips And trip "TR-131" carries 5,000.00 of it and trip "TR-132" carries 3,000.00 And customer "C-104" buys under contract "K-104-2" with 30-day payment terms Given the invoice for trip "TR-131" is raised and the trip has left with it When trip "TR-131" is confirmed delivered | J40: Then its statuses are "Partly invoiced", "Partly delivered" and "Unpaid"
A41: UAT-40 | B41: sale-statuses | C41: A delivered sale waits on its credit terms | D41: sale-statuses | E41: in state: Invoiced, Delivered, Unpaid | F41: R10 | G41: T11, T17, T12 | H41: D8, D16, D17 | I41: Given order "SO-2060" for 8,000.00 ships on two trips And trip "TR-131" carries 5,000.00 of it and trip "TR-132" carries 3,000.00 And customer "C-104" buys under contract "K-104-2" with 30-day payment terms Given the invoices for trips "TR-131" and "TR-132" were raised on 2 March and 5 March And both trips are confirmed delivered | J41: Then its statuses are "Invoiced", "Delivered" and "Unpaid" And its invoices fall due on 1 April and 4 April
...

Sheet Sign-off
A1: Story | B1: Feature | C1: Owning department | D1: Signs | E1: Scenarios | F1: Passed | G1: Failed | H1: Open severity 1 defects | I1: Decision | J1: Signed by (role) | K1: Date | L1: Note
A2: delivery-trip | B2: Ship exactly what was planned, and freeze what was delivered | C2: Logistics | D2: Logistics lead (D14) | E2: =COUNTIFS(UAT!$B$2:$B$48,A2) | F2: =COUNTIFS(UAT!$B$2:$B$48,A2,UAT!$L$2:$L$48,"Pass") | G2: =COUNTIFS(UAT!$B$2:$B$48,A2,UAT!$L$2:$L$48,"Fail") | H2: =COUNTIFS(Defects!$C$2:$C$31,A2,Defects!$D$2:$D$31,"1",Defects!$H$2:$H$31,"<>Closed")
A3: material-request | B3: Issue materials to the workshop, and never cancel what has left the warehouse | C3: Production | D3: Factory manager (material requests and issues, D6) | E3: =COUNTIFS(UAT!$B$2:$B$48,A3) | F3: =COUNTIFS(UAT!$B$2:$B$48,A3,UAT!$L$2:$L$48,"Pass") | G3: =COUNTIFS(UAT!$B$2:$B$48,A3,UAT!$L$2:$L$48,"Fail") | H3: =COUNTIFS(Defects!$C$2:$C$31,A3,Defects!$D$2:$D$31,"1",Defects!$H$2:$H$31,"<>Closed")
A4: order-closure | B4: Close an order the right way for how far it got | C4: Sales | D4: Sales lead, with the logistics lead (closure rules, D6) | E4: =COUNTIFS(UAT!$B$2:$B$48,A4) | F4: =COUNTIFS(UAT!$B$2:$B$48,A4,UAT!$L$2:$L$48,"Pass") | G4: =COUNTIFS(UAT!$B$2:$B$48,A4,UAT!$L$2:$L$48,"Fail") | H4: =COUNTIFS(Defects!$C$2:$C$31,A4,Defects!$D$2:$D$31,"1",Defects!$H$2:$H$31,"<>Closed")
A5: order-lifecycle | B5: Take a sales order from request to logistics | C5: Sales | D5: Sales lead | E5: =COUNTIFS(UAT!$B$2:$B$48,A5) | F5: =COUNTIFS(UAT!$B$2:$B$48,A5,UAT!$L$2:$L$48,"Pass") | G5: =COUNTIFS(UAT!$B$2:$B$48,A5,UAT!$L$2:$L$48,"Fail") | H5: =COUNTIFS(Defects!$C$2:$C$31,A5,Defects!$D$2:$D$31,"1",Defects!$H$2:$H$31,"<>Closed")
A6: purchase-order | B6: Buy materials without an approval step inside the system | C6: Purchasing | D6: Logistics manager, who signs purchase orders on paper (D9) | E6: =COUNTIFS(UAT!$B$2:$B$48,A6) | F6: =COUNTIFS(UAT!$B$2:$B$48,A6,UAT!$L$2:$L$48,"Pass") | G6: =COUNTIFS(UAT!$B$2:$B$48,A6,UAT!$L$2:$L$48,"Fail") | H6: =COUNTIFS(Defects!$C$2:$C$31,A6,Defects!$D$2:$D$31,"1",Defects!$H$2:$H$31,"<>Closed")
A7: receivables | B7: Invoice every trip, and collect each invoice on its contract's terms | C7: Accounting | D7: Chief accountant (payment terms, credit hold and collection, D17) | E7: =COUNTIFS(UAT!$B$2:$B$48,A7) | F7: =COUNTIFS(UAT!$B$2:$B$48,A7,UAT!$L$2:$L$48,"Pass") | G7: =COUNTIFS(UAT!$B$2:$B$48,A7,UAT!$L$2:$L$48,"Fail") | H7: =COUNTIFS(Defects!$C$2:$C$31,A7,Defects!$D$2:$D$31,"1",Defects!$H$2:$H$31,"<>Closed")
A8: sale-statuses | B8: See how far a sale has got: invoiced, delivered, paid | C8: Accounting | D8: Finance lead (legal status combinations, D8) | E8: =COUNTIFS(UAT!$B$2:$B$48,A8) | F8: =COUNTIFS(UAT!$B$2:$B$48,A8,UAT!$L$2:$L$48,"Pass") | G8: =COUNTIFS(UAT!$B$2:$B$48,A8,UAT!$L$2:$L$48,"Fail") | H8: =COUNTIFS(Defects!$C$2:$C$31,A8,Defects!$D$2:$D$31,"1",Defects!$H$2:$H$31,"<>Closed")
A9: voucher-posting | B9: Save, post and correct accounting vouchers without ever deleting one | C9: Accounting | D9: Chief accountant (posting policy, D10) | E9: =COUNTIFS(UAT!$B$2:$B$48,A9) | F9: =COUNTIFS(UAT!$B$2:$B$48,A9,UAT!$L$2:$L$48,"Pass") | G9: =COUNTIFS(UAT!$B$2:$B$48,A9,UAT!$L$2:$L$48,"Fail") | H9: =COUNTIFS(Defects!$C$2:$C$31,A9,Defects!$D$2:$D$31,"1",Defects!$H$2:$H$31,"<>Closed")

Sheet Test data
A1: Record | B1: Kind | C1: Start it in | D1: Used by rows
A2: C-104 | B2: customer | C2: as the row's steps say | D2: UAT-17, UAT-18, UAT-19, UAT-20, UAT-21, UAT-22, UAT-30, UAT-31, UAT-32, UAT-33, UAT-34, UAT-35, UAT-36, UAT-37, UAT-38, UAT-39, UAT-40, UAT-41, UAT-42, UAT-43, UAT-44
A3: K-104-2 | B3: customer contract | C3: as the row's steps say | D3: UAT-19, UAT-20, UAT-30, UAT-31, UAT-32, UAT-33, UAT-34, UAT-35, UAT-36, UAT-37, UAT-38, UAT-39, UAT-40, UAT-41, UAT-42
A4: TR-118 | B4: delivery trip | C4: In transit, Issued, Planned | D4: UAT-01, UAT-02, UAT-03, UAT-04, UAT-05, UAT-06
A5: TR-131 | B5: delivery trip | C5: Issued | D5: UAT-30, UAT-31, UAT-32, UAT-33, UAT-34, UAT-35, UAT-36, UAT-37, UAT-38, UAT-39, UAT-40, UAT-41, UAT-42
A6: TR-132 | B6: delivery trip | C6: Planned | D6: UAT-31, UAT-37, UAT-38, UAT-39, UAT-40, UAT-41, UAT-42
A7: MR-310 | B7: material request | C7: Issuing, Open | D7: UAT-07, UAT-08, UAT-09, UAT-10, UAT-11, UAT-12
A8: MR-311 | B8: material request | C8: Open | D8: UAT-12
A9: PO-5110 | B9: purchase order | C9: Open, Received | D9: UAT-23, UAT-24, UAT-25, UAT-26, UAT-28, UAT-29
A10: PO-5120 | B10: purchase order | C10: as the row's steps say | D10: UAT-27
A11: INV-390 | B11: sales invoice | C11: Raised | D11: UAT-02
A12: INV-401 | B12: sales invoice | C12: Raised | D12: UAT-30, UAT-32, UAT-35, UAT-36
... A21: V-07 | B21: supplier | C21: as the row's steps say | D21: UAT-23

Sheet Defects
A1: Defect | B1: UAT row | C1: Story | D1: Severity | E1: What happened | F1: Found by (role) | G1: Owner | H1: Status | I1: Date found | J1: Date closed
A2: DEF-01 | C2: =IF(B2="","",IFERROR(INDEX(UAT!$B$2:$B$48,MATCH(B2,UAT!$A$2:$A$48,0)),"not a UAT row"))
A3: DEF-02 | C3: =IF(B3="","",IFERROR(INDEX(UAT!$B$2:$B$48,MATCH(B3,UAT!$A$2:$A$48,0)),"not a UAT row"))
A4: DEF-03 | C4: =IF(B4="","",IFERROR(INDEX(UAT!$B$2:$B$48,MATCH(B4,UAT!$A$2:$A$48,0)),"not a UAT row"))
A5: DEF-04 | C5: =IF(B5="","",IFERROR(INDEX(UAT!$B$2:$B$48,MATCH(B5,UAT!$A$2:$A$48,0)),"not a UAT row"))
A6: DEF-05 | C6: =IF(B6="","",IFERROR(INDEX(UAT!$B$2:$B$48,MATCH(B6,UAT!$A$2:$A$48,0)),"not a UAT row"))
A7: DEF-06 | C7: =IF(B7="","",IFERROR(INDEX(UAT!$B$2:$B$48,MATCH(B7,UAT!$A$2:$A$48,0)),"not a UAT row"))
A8: DEF-07 | C8: =IF(B8="","",IFERROR(INDEX(UAT!$B$2:$B$48,MATCH(B8,UAT!$A$2:$A$48,0)),"not a UAT row"))
A9: DEF-08 | C9: =IF(B9="","",IFERROR(INDEX(UAT!$B$2:$B$48,MATCH(B9,UAT!$A$2:$A$48,0)),"not a UAT row"))
A10: DEF-09 | C10: =IF(B10="","",IFERROR(INDEX(UAT!$B$2:$B$48,MATCH(B10,UAT!$A$2:$A$48,0)),"not a UAT row"))
A11: DEF-10 | C11: =IF(B11="","",IFERROR(INDEX(UAT!$B$2:$B$48,MATCH(B11,UAT!$A$2:$A$48,0)),"not a UAT row"))
A12: DEF-11 | C12: =IF(B12="","",IFERROR(INDEX(UAT!$B$2:$B$48,MATCH(B12,UAT!$A$2:$A$48,0)),"not a UAT row"))
A13: DEF-12 | C13: =IF(B13="","",IFERROR(INDEX(UAT!$B$2:$B$48,MATCH(B13,UAT!$A$2:$A$48,0)),"not a UAT row"))
... A31: DEF-30 | C31: =IF(B31="","",IFERROR(INDEX(UAT!$B$2:$B$48,MATCH(B31,UAT!$A$2:$A$48,0)),"not a UAT row"))

Sheet Change log
A1: Date | B1: Change | C1: By (role)
A2: 2026-09-29 | B2: First version, generated from three stories | C2: Product owner
A3: 2026-09-30 | B3: Rebuilt on the state model: six stories, every error path a refused move | C3: Product owner
A4: 2026-09-30 | B4: Every row carries its state transition and rule; map steps checked (second read) | C4: Product owner
A5: 2026-09-30 | B5: B2B receivables: an invoice per trip before dispatch, the credit hold, oldest-first allocation, part credit notes, returns; the sales-invoice and sale-status stories | C5: Product owner
A6: 2026-09-30 | B6: The draft stock form (D15); the trip Issued state; partial receipts and issues; the material-request story; purchase-order scenarios in the real sequence | C6: Product owner
A7: 2026-09-30 | B7: Map steps per row; the Test data and Defects sheets; open severity 1 defects on Sign-off; the tester role suggested | C7: Product owner
